<?xml version='1.0' encoding='utf-8'?>
<robot name="h1_5">

  <!-- [CAUTION] uncomment when convert to mujoco -->
  <!-- <link name="world"></link>
  <joint name="floating_base_joint" type="floating">
    <parent link="world"/>
    <child link="pelvis"/>
  </joint> -->

  <link name="pelvis">
    <inertial>
      <origin xyz="-0.0004 3.7E-05 -0.046864" rpy="0 0 0" />
      <mass value="5.983" />
      <inertia ixx="49168.411E-06" ixy="-19.869E-06" ixz="-48.460E-06" iyy="9025.844E-06" iyz="3.431E-06" izz="53155.891E-06" />
    </inertial>
    </link>

  <!-- L Leg -->
  <link name="left_hip_yaw_link">
    <inertial>
      <origin xyz="0 -0.026197 0.006647" rpy="0 0 0" />
      <mass value="2.829" />
      <inertia ixx="4553.605E-06" ixy="0.005E-06" ixz="0.817E-06" iyy="5688.730E-06" iyz="-345.157E-06" izz="3548.907E-06" />
    </inertial>
    </link>
  <joint name="left_hip_yaw_joint" type="revolute">
    <origin xyz="0 0.0875 -0.1632" rpy="0 0 0" />
    <parent link="pelvis" />
    <child link="left_hip_yaw_link" />
    <axis xyz="0 0 1" />
    <limit lower="-0.43" upper="0.43" effort="200" velocity="23" />
  </joint>
  <link name="left_hip_pitch_link">
    <inertial>
      <origin xyz="-0.00781 -0.004724 -0.000063" rpy="0 0 0" />
      <mass value="2.920" />
      <inertia ixx="5594.7E-06" ixy="143.308E-06" ixz="-11.847E-06" iyy="3862.581E-06" iyz="-9.607E-06" izz="4450.563E-06" />
    </inertial>
    </link>
  <joint name="left_hip_pitch_joint" type="revolute">
    <origin xyz="0 0.0755 0" rpy="0 0 0" />
    <parent link="left_hip_yaw_link" />
    <child link="left_hip_pitch_link" />
    <axis xyz="0 1 0" />
    <limit lower="-3.14" upper="2.5" effort="200" velocity="23" />
  </joint>
  <link name="left_hip_roll_link">
    <inertial>
      <origin xyz="0.004171 -0.008576 -0.194509" rpy="0 0 0" />
      <mass value="4.962" />
      <inertia ixx="46305.869E-06" ixy="-322.626E-06" ixz="-1199.703E-06" iyy="47955.402E-06" iyz="288.147E-06" izz="8914.518E-06" />
    </inertial>
    </link>
  <joint name="left_hip_roll_joint" type="revolute">
    <origin xyz="0 0 0" rpy="0 0 0" />
    <parent link="left_hip_pitch_link" />
    <child link="left_hip_roll_link" />
    <axis xyz="1 0 0" />
    <limit lower="-0.43" upper="3.14" effort="200" velocity="23" />
  </joint>
  <link name="left_knee_link">
    <inertial>
      <origin xyz="0.000179 0.000121 -0.168936" rpy="0 0 0" />
      <mass value="3.839" />
      <inertia ixx="39002.363e-6" ixy="-72.364e-6" ixz="-794.506e-6" iyy="39042.376e-6" iyz="-18.663e-6" izz="5029.829e-6" />
    </inertial>
    </link>
  <joint name="left_knee_joint" type="revolute">
    <origin xyz="0 0 -0.4" rpy="0 0 0" />
    <parent link="left_hip_roll_link" />
    <child link="left_knee_link" />
    <axis xyz="0 1 0" />
    <limit lower="-0.12" upper="2.19" effort="300" velocity="14"/>
  </joint>
  <link name="left_ankle_pitch_link">
    <inertial>
      <origin xyz="-0.000294 0 -0.010794" rpy="0 0 0" />
      <mass value="0.102" />
      <inertia ixx="0.000023944" ixy="0" ixz="0.000000121" iyy="0.000021837" iyz="0" izz="0.000013414" />
    </inertial>
    </link>
  <joint name="left_ankle_pitch_joint" type="revolute">
    <origin xyz="0 0 -0.4" rpy="0 0 0" />
    <parent link="left_knee_link" />
    <child link="left_ankle_pitch_link" />
    <axis xyz="0 1 0" />
    <limit lower="-0.897334" upper="0.523598" effort="60" velocity="9" />
  </joint>
  <link name="left_ankle_roll_link">
    <inertial>
      <origin xyz="0.029589 0 -0.015973" rpy="0 0 0" />
      <mass value="0.747" />
      <inertia ixx="648.830e-6" ixy="0" ixz="158.380e-6" iyy="3435.339e-6" iyz="0" izz="3583.259e-6" />
    </inertial>
    </link>
  <joint name="left_ankle_roll_joint" type="revolute">
    <origin xyz="0 0 -0.02" rpy="0 0 0" />
    <parent link="left_ankle_pitch_link" />
    <child link="left_ankle_roll_link" />
    <axis xyz="1 0 0" />
    <limit lower="-0.261799" upper="0.261799" effort="40" velocity="9" />
  </joint>

  <!-- R Leg -->
  <link name="right_hip_yaw_link">
    <inertial>
      <origin xyz="0 0.026197 0.006647" rpy="0 0 0" />
      <mass value="2.829" />
      <inertia ixx="4553.605E-06" ixy="-0.005E-06" ixz="0.817E-06" iyy="5688.730E-06" iyz="345.157E-06" izz="3548.907E-06" />
    </inertial>
    </link>
  <joint name="right_hip_yaw_joint" type="revolute">
    <origin xyz="0 -0.0875 -0.1632" rpy="0 0 0" />
    <parent link="pelvis" />
    <child link="right_hip_yaw_link" />
    <axis xyz="0 0 1" />
    <limit lower="-0.43" upper="0.43" effort="200" velocity="23" />
  </joint>
  <link name="right_hip_pitch_link">
    <inertial>
      <origin xyz="-0.00781 0.004724 -0.000063" rpy="0 0 0" />
      <mass value="2.920" />
      <inertia ixx="5594.7E-06" ixy="-143.308E-06" ixz="-11.847E-06" iyy="3862.581E-06" iyz="9.607E-06" izz="4450.563E-06" />
    </inertial>
    </link>
  <joint name="right_hip_pitch_joint" type="revolute">
    <origin xyz="0 -0.0755 0" rpy="0 0 0" />
    <parent link="right_hip_yaw_link" />
    <child link="right_hip_pitch_link" />
    <axis xyz="0 1 0" />
    <limit lower="-3.14" upper="2.5" effort="200" velocity="23" />
  </joint>
  <link name="right_hip_roll_link">
    <inertial>
      <origin xyz="0.004171 0.008576 -0.194509" rpy="0 0 0" />
      <mass value="4.962" />
      <inertia ixx="46305.869E-06" ixy="322.626E-06" ixz="-1199.703E-06" iyy="47955.402E-06" iyz="-288.147E-06" izz="8914.518E-06" />
    </inertial>
    </link>
  <joint name="right_hip_roll_joint" type="revolute">
    <origin xyz="0 0 0" rpy="0 0 0" />
    <parent link="right_hip_pitch_link" />
    <child link="right_hip_roll_link" />
    <axis xyz="1 0 0" />
    <limit lower="-3.14" upper="0.43" effort="200" velocity="23" />
  </joint>
  <link name="right_knee_link">
    <inertial>
      <origin xyz="0.000179 -0.000121 -0.168936" rpy="0 0 0" />
      <mass value="3.839" />
      <inertia ixx="39002.363e-6" ixy="72.364e-6" ixz="-794.506e-6" iyy="39042.376e-6" iyz="18.663e-6" izz="5029.829e-6" />
    </inertial>
    </link>
  <joint name="right_knee_joint" type="revolute">
    <origin xyz="0 0 -0.4" rpy="0 0 0" />
    <parent link="right_hip_roll_link" />
    <child link="right_knee_link" />
    <axis xyz="0 1 0" />
    <limit lower="-0.12" upper="2.19" effort="300" velocity="14"/>
  </joint>
  <link name="right_ankle_pitch_link">
    <inertial>
      <origin xyz="-0.000294 0 -0.010794" rpy="0 0 0" />
      <mass value="0.102" />
      <inertia ixx="0.000023944" ixy="0" ixz="0.000000121" iyy="0.000021837" iyz="0" izz="0.000013414" />
    </inertial>
    </link>
  <joint name="right_ankle_pitch_joint" type="revolute">
    <origin xyz="0 0 -0.4" rpy="0 0 0" />
    <parent link="right_knee_link" />
    <child link="right_ankle_pitch_link" />
    <axis xyz="0 1 0" />
    <limit lower="-0.897334" upper="0.523598" effort="60" velocity="9" />
  </joint>
  <link name="right_ankle_roll_link">
    <inertial>
      <origin xyz="0.029589 0 -0.015973" rpy="0 0 0" />
      <mass value="0.747" />
      <inertia ixx="648.830e-6" ixy="0" ixz="158.380e-6" iyy="3435.339e-6" iyz="0" izz="3583.259e-6" />
    </inertial>
    </link>
  <joint name="right_ankle_roll_joint" type="revolute">
    <origin xyz="0 0 -0.02" rpy="0 0 0" />
    <parent link="right_ankle_pitch_link" />
    <child link="right_ankle_roll_link" />
    <axis xyz="1 0 0" />
    <limit lower="-0.261799" upper="0.261799" effort="40" velocity="9" />
  </joint>

  <!-- Torso -->
  <link name="torso_link">
    <inertial>
      <origin xyz="0.000489 0.002797 0.20484" rpy="0 0 0" />
      <mass value="17.789" />
      <inertia ixx="0.4873" ixy="-0.00053763" ixz="0.0020276" iyy="0.40963" iyz="-0.00074582" izz="0.12785" />
    </inertial>
    </link>
  <joint name="torso_joint" type="revolute">
    <origin xyz="0 0 0" rpy="0 0 0" />
    <parent link="pelvis" />
    <child link="torso_link" />
    <axis xyz="0 0 1" />
    <limit lower="-2.35" upper="2.35" effort="200" velocity="23" />
  </joint>

  <!-- L arm -->
  <link name="left_shoulder_pitch_link">
    <inertial>
      <origin xyz="0.003053 0.06042 -0.0059" rpy="0 0 0" />
      <mass value="1.327" />
      <inertia ixx="0.00058661" ixy="-2.0157E-05" ixz="2.985E-06" iyy="0.0003989" iyz="2.238E-05" izz="0.00052936" />
    </inertial>
    </link>
  <joint name="left_shoulder_pitch_joint" type="revolute">
    <origin xyz="0 0.14806 0.42333" rpy="0.2618 0 0" />
    <parent link="torso_link" />
    <child link="left_shoulder_pitch_link" />
    <axis xyz="0 1 0" />
    <limit lower="-3.14" upper="1.57" effort="40" velocity="9" />
  </joint>
  <link name="left_shoulder_roll_link">
    <inertial>
      <origin xyz="-0.030932 -1E-06 -0.10609" rpy="0 0 0" />
      <mass value="1.393" />
      <inertia ixx="0.0018408" ixy="3.98E-07" ixz="-0.00048324" iyy="0.001934638" iyz="1.61E-07" izz="0.000617733" />
    </inertial>
    </link>
  <joint name="left_shoulder_roll_joint" type="revolute">
    <origin xyz="0.0342 0.061999 -0.0060011" rpy="-0.2618 0 0" />
    <parent link="left_shoulder_pitch_link" />
    <child link="left_shoulder_roll_link" />
    <axis xyz="1 0 0" />
    <limit lower="-0.38" upper="3.4" effort="40" velocity="9" />
  </joint>
  <link name="left_shoulder_yaw_link">
    <inertial>
      <origin xyz="0.004583 0.001128 -0.001128" rpy="0 0 0" />
      <mass value="1.505" />
      <inertia ixx="0.004199" ixy="-1.7786E-05" ixz="0.00018372" iyy="0.0043139" iyz="9.278E-05" izz="0.00065755" />
    </inertial>
    </link>
  <joint name="left_shoulder_yaw_joint" type="revolute">
    <origin xyz="-0.0342 0 -0.1456" rpy="0 0 0" />
    <parent link="left_shoulder_roll_link" />
    <child link="left_shoulder_yaw_link" />
    <axis xyz="0 0 1" />
    <limit lower="-2.66" upper="3.01" effort="18" velocity="20" />
  </joint>
  <link name="left_elbow_link">
    <inertial>
      <origin xyz="0.077092 -0.028751 -0.009714 " rpy="0 0 0" />
      <mass value="0.691" />
      <inertia ixx="0.000318491" ixy="0.000224554" ixz="6.62076E-05" iyy="0.000861224" iyz="-2.3329E-05" izz="0.000897899" />
    </inertial>
    </link>
  <joint name="left_elbow_joint" type="revolute">
    <origin xyz="0.006 0.0329 -0.182" rpy="0 0 0" />
    <parent link="left_shoulder_yaw_link" />
    <child link="left_elbow_link" />
    <axis xyz="0 1 0" />
    <limit lower="-0.95" upper="3.18" effort="18" velocity="20" />
  </joint>

  <link name="left_wrist_roll_link">
    <inertial>
      <origin xyz="0.035281 -0.002320 0.000337" rpy="0 0 0" />
      <mass value="0.683" />
      <inertia ixx="0.000313275" ixy="0.000016521" ixz="-0.000002501" iyy="0.000310412" iyz="0.000005435" izz="0.000345998" />
    </inertial>
    </link>
  <joint name="left_wrist_roll_joint" type="revolute">
    <origin xyz="0.121 -0.0329 -0.011" rpy="0 0 0" />
    <parent link="left_elbow_link" />
    <child link="left_wrist_roll_link" />
    <axis xyz="1 0 0" />
    <limit lower="-3.01" upper="2.75" effort="19" velocity="31.4" />
  </joint>

  <link name="left_wrist_pitch_link">
    <inertial>
      <origin xyz="0.020395 0.000036 -0.002973" rpy="0 0 0" />
      <mass value="0.484" />
      <inertia ixx="0.000071364" ixy="0.000000308" ixz="0.000001485" iyy="0.000069915" iyz="-0.000000088" izz="0.000070702" />
    </inertial>
    </link>
  <joint name="left_wrist_pitch_joint" type="revolute">
    <origin xyz="0.087 0 0" rpy="0 0 0" />
    <parent link="left_wrist_roll_link" />
    <child link="left_wrist_pitch_link" />
    <axis xyz="0 1 0" />
    <limit lower="-0.4625" upper="0.4625" effort="19" velocity="31.4" />
  </joint>
  <link name="left_wrist_yaw_link">
    <inertial>
      <origin xyz="0.027967 0.000096 0.000739" rpy="0 0 0" />
      <mass value="0.124" />
      <inertia ixx="137.3e-6" ixy="-0.171e-6" ixz="2.942e-6" iyy="169.998e-6" iyz="-0.025e-6" izz="84.808e-6" />
    </inertial>
    <!-- <collision>
      <origin xyz="0 0 0" rpy="0 0 0"/>
      <geometry>
        <mesh filename="meshes/wrist_yaw_link.STL"/>
      </geometry>
    </collision> -->
  </link>
  <joint name="left_wrist_yaw_joint" type="revolute">
    <origin xyz="0.020 0 0" rpy="0 0 0" />
    <parent link="left_wrist_pitch_link" />
    <child link="left_wrist_yaw_link" />
    <axis xyz="0 0 1" />
    <limit lower="-1.27" upper="1.27" effort="19" velocity="31.4" />
  </joint>

  <!-- R arm -->
  <link name="right_shoulder_pitch_link">
    <inertial>
      <origin xyz="0.003053 -0.06042 -0.0059" rpy="0 0 0" />
      <mass value="1.327" />
      <inertia ixx="0.00058661" ixy="2.0157E-05" ixz="2.985E-06" iyy="0.0003989" iyz="-2.238E-05" izz="0.00052936" />
    </inertial>
    </link>
  <joint name="right_shoulder_pitch_joint" type="revolute">
    <origin xyz="0 -0.14806 0.42333" rpy="-0.2618 0 0" />
    <parent link="torso_link" />
    <child link="right_shoulder_pitch_link" />
    <axis xyz="0 1 0" />
    <limit lower="-3.14" upper="1.57" effort="40" velocity="9" />
  </joint>
  <link name="right_shoulder_roll_link">
    <inertial>
      <origin xyz="-0.030932 1E-06 -0.10609" rpy="0 0 0" />
      <mass value="1.393" />
      <inertia ixx="0.0018408" ixy="-3.98E-07" ixz="-0.00048324" iyy="0.001934638" iyz="-1.61E-07" izz="0.000617733" />
    </inertial>
    </link>
  <joint name="right_shoulder_roll_joint" type="revolute">
    <origin xyz="0.0342 -0.061999 -0.0060011" rpy="0.2618 0 0" />
    <parent link="right_shoulder_pitch_link" />
    <child link="right_shoulder_roll_link" />
    <axis xyz="1 0 0" />
    <limit lower="-3.4" upper="0.38" effort="40" velocity="9" />
  </joint>
  <link name="right_shoulder_yaw_link">
    <inertial>
      <origin xyz="0.004583 -0.001128 -0.001128" rpy="0 0 0" />
      <mass value="1.505" />
      <inertia ixx="0.004199" ixy="1.7786E-05" ixz="0.00018372" iyy="0.0043139" iyz="-9.278E-05" izz="0.00065755" />

    </inertial>
    </link>
  <joint name="right_shoulder_yaw_joint" type="revolute">
    <origin xyz="-0.0342 0 -0.1456" rpy="0 0 0" />
    <parent link="right_shoulder_roll_link" />
    <child link="right_shoulder_yaw_link" />
    <axis xyz="0 0 1" />
    <limit lower="-3.01" upper="2.66" effort="18" velocity="20" />
  </joint>
  <link name="right_elbow_link">
    <inertial>
      <origin xyz="0.077092 0.028751 -0.009714 " rpy="0 0 0" />
      <mass value="0.691" />
      <inertia ixx="0.000318491" ixy="-0.000224554" ixz="6.62076E-05" iyy="0.000861224" iyz="2.3329E-05" izz="0.000897899" />
    </inertial>
    </link>
  <joint name="right_elbow_joint" type="revolute">
    <origin xyz="0.006 -0.0329 -0.182" rpy="0 0 0" />
    <parent link="right_shoulder_yaw_link" />
    <child link="right_elbow_link" />
    <axis xyz="0 1 0" />
    <limit lower="-0.95" upper="3.18" effort="18" velocity="20" />
  </joint>

  <link name="right_wrist_roll_link">
    <inertial>
      <origin xyz="0.035281 -0.002320 0.000337" rpy="0 0 0" />
      <mass value="0.683" />
      <inertia ixx="0.000313275" ixy="0.000016521" ixz="-0.000002501" iyy="0.000310412" iyz="0.000005435" izz="0.000345998" />
    </inertial>
    </link>
  <joint name="right_wrist_roll_joint" type="revolute">
    <origin xyz="0.121 0.0329 -0.011" rpy="0 0 0" />
    <parent link="right_elbow_link" />
    <child link="right_wrist_roll_link" />
    <axis xyz="1 0 0" />
    <limit lower="-2.75" upper="3.01" effort="19" velocity="31.4" />
  </joint>

  <link name="right_wrist_pitch_link">
    <inertial>
      <origin xyz="0.020395 0.000036 -0.002973" rpy="0 0 0" />
      <mass value="0.484" />
      <inertia ixx="0.000071364" ixy="0.000000308" ixz="0.000001485" iyy="0.000069915" iyz="-0.000000088" izz="0.000070702" />
    </inertial>
    </link>
  <joint name="right_wrist_pitch_joint" type="revolute">
    <origin xyz="0.087 0 0" rpy="0 0 0" />
    <parent link="right_wrist_roll_link" />
    <child link="right_wrist_pitch_link" />
    <axis xyz="0 1 0" />
    <limit lower="-0.4625" upper="0.4625" effort="19" velocity="31.4" />
  </joint>
  <link name="right_wrist_yaw_link">
    <inertial>
      <origin xyz="0.027967 -0.000096 0.000739" rpy="0 0 0" />
      <mass value="0.124" />
      <inertia ixx="137.3e-6" ixy="0.171e-6" ixz="2.942e-6" iyy="169.998e-6" iyz="0.025e-6" izz="84.808e-6" />
    </inertial>
    <!-- <collision>
      <origin xyz="0 0 0" rpy="0 0 0"/>
      <geometry>
        <mesh filename="meshes/wrist_yaw_link.STL"/>
      </geometry>
    </collision> -->
  </link>
  <joint name="right_wrist_yaw_joint" type="revolute">
    <origin xyz="0.020 0 0" rpy="0 0 0" />
    <parent link="right_wrist_pitch_link" />
    <child link="right_wrist_yaw_link" />
    <axis xyz="0 0 1" />
    <limit lower="-1.27" upper="1.27" effort="19" velocity="31.4" />
  </joint>

  <!-- LOGO -->
  <link name="logo_link">
    </link>
  <joint name="logo_joint" type="fixed">
    <origin xyz="0 0 0" rpy="0 0 0" />
    <parent link="torso_link" />
    <child link="logo_link" />
    <axis xyz="0 0 0" />
  </joint>

  <!-- IMU -->
  <link name="imu_link" />
  <joint name="imu_joint" type="fixed">
    <origin xyz="-0.04233868314 0.00166 0.152067" rpy="0 0 0" />
    <parent link="torso_link" />
    <child link="imu_link" />
  </joint>

  <!-- L Gripper -->
  <joint name="L_base_link_joint" type="fixed">
    <origin xyz="0.054 0 0" rpy="0 0 1.5707963267948966192313216916398" />
    <parent link="left_wrist_yaw_link" />
    <child link="L_hand_base_link" />
  </joint>
  <link name="L_hand_base_link">
    <inertial>
      <origin xyz="-0.002551 -0.066047 -0.0019357" rpy="0 0 0" />
      <mass value="0.14143" />
      <inertia ixx="0.0001234" ixy="2.1995E-06" ixz="-1.7694E-06" iyy="8.3835E-05" iyz="1.5968E-06" izz="7.7231E-05" />
    </inertial>
    </link>
  <link name="L_thumb_proximal_base">
    <inertial>
      <origin xyz="0.0048817 0.00038782 -0.00722" rpy="0 0 0" />
      <mass value="0.0018869" />
      <inertia ixx="5.5158E-08" ixy="-1.1803E-08" ixz="-4.6743E-09" iyy="8.2164E-08" iyz="-1.3521E-09" izz="6.7434E-08" />
    </inertial>
    </link>
  <joint name="L_thumb_proximal_yaw_joint" type="revolute">
    <origin xyz="-0.01696 -0.0691 0.02045" rpy="1.5708 -1.5708 0" />
    <parent link="L_hand_base_link" />
    <child link="L_thumb_proximal_base" />
    <axis xyz="0 0 1" />
    <limit lower="-0.1" upper="1.3" effort="1" velocity="0.5" />
  </joint>
  <link name="L_thumb_proximal">
    <inertial>
      <origin xyz="0.021936 -0.01279 -0.0080386" rpy="0 0 0" />
      <mass value="0.0066101" />
      <inertia ixx="1.5693E-06" ixy="7.8339E-07" ixz="8.5959E-10" iyy="1.7356E-06" iyz="1.0378E-09" izz="2.787E-06" />
    </inertial>
    </link>
  <joint name="L_thumb_proximal_pitch_joint" type="revolute">
    <origin xyz="0.0099867 0.0098242 -0.0089" rpy="-1.5708 0 0.16939" />
    <parent link="L_thumb_proximal_base" />
    <child link="L_thumb_proximal" />
    <axis xyz="0 0 -1" />
    <limit lower="-0.1" upper="0.6" effort="1" velocity="0.5" />
  </joint>
  <link name="L_thumb_intermediate">
    <inertial>
      <origin xyz="0.0095531 0.0016282 -0.0072002" rpy="0 0 0" />
      <mass value="0.0037844" />
      <inertia ixx="3.6981E-07" ixy="9.8603E-08" ixz="-2.8173E-12" iyy="3.2395E-07" iyz="-2.8028E-12" izz="4.6532E-07" />
    </inertial>
    </link>
  <joint name="L_thumb_intermediate_joint" type="revolute">
    <origin xyz="0.04407 -0.034553 -0.0008" rpy="0 0 0" />
    <parent link="L_thumb_proximal" />
    <child link="L_thumb_intermediate" />
    <axis xyz="0 0 -1" />
    <limit lower="0" upper="0.8" effort="1" velocity="0.5" />
    <mimic joint="L_thumb_proximal_pitch_joint" multiplier="1.6" offset="0" />
  </joint>
  <link name="L_thumb_distal">
    <inertial>
      <origin xyz="0.0092888 -0.004953 -0.0060033" rpy="0 0 0" />
      <mass value="0.003344" />
      <inertia ixx="1.3632E-07" ixy="5.6787E-08" ixz="-9.1939E-11" iyy="1.4052E-07" iyz="1.2145E-10" izz="2.0026E-07" />
    </inertial>
    </link>
  <joint name="L_thumb_distal_joint" type="revolute">
    <origin xyz="0.020248 -0.010156 -0.0012" rpy="0 0 0" />
    <parent link="L_thumb_intermediate" />
    <child link="L_thumb_distal" />
    <axis xyz="0 0 -1" />
    <limit lower="0" upper="1.2" effort="1" velocity="0.5" />
    <mimic joint="L_thumb_proximal_pitch_joint" multiplier="2.4" offset="0" />
  </joint>
  <link name="L_index_proximal">
    <inertial>
      <origin xyz="0.0012971 -0.011934 -0.0059998" rpy="0 0 0" />
      <mass value="0.0042405" />
      <inertia ixx="6.6215E-07" ixy="1.8442E-08" ixz="1.3746E-12" iyy="2.1167E-07" iyz="-1.4773E-11" izz="6.9402E-07" />
    </inertial>
    </link>
  <joint name="L_index_proximal_joint" type="revolute">
    <origin xyz="0.00028533 -0.13653 0.032268" rpy="-0.034907 0 0" />
    <parent link="L_hand_base_link" />
    <child link="L_index_proximal" />
    <axis xyz="0 0 -1" />
    <limit lower="0" upper="1.7" effort="1" velocity="0.5" />
  </joint>
  <link name="L_index_intermediate">
    <inertial>
      <origin xyz="0.0021753 -0.019567 -0.005" rpy="0 0 0" />
      <mass value="0.0045682" />
      <inertia ixx="7.6284E-07" ixy="-8.063E-08" ixz="3.6797E-13" iyy="9.4308E-08" iyz="1.5743E-13" izz="7.8176E-07" />
    </inertial>
    </link>
  <joint name="L_index_intermediate_joint" type="revolute">
    <origin xyz="-0.0024229 -0.032041 -0.001" rpy="0 0 0" />
    <parent link="L_index_proximal" />
    <child link="L_index_intermediate" />
    <axis xyz="0 0 -1" />
    <limit lower="0" upper="1.7" effort="1" velocity="0.5" />
    <mimic joint="L_index_proximal_joint" multiplier="1" offset="0" />
  </joint>
  <link name="L_middle_proximal">
    <inertial>
      <origin xyz="0.0012971 -0.011934 -0.0059999" rpy="0 0 0" />
      <mass value="0.0042405" />
      <inertia ixx="6.6215E-07" ixy="1.8442E-08" ixz="1.2299E-12" iyy="2.1167E-07" iyz="-1.4484E-11" izz="6.9402E-07" />
    </inertial>
    </link>
  <joint name="L_middle_proximal_joint" type="revolute">
    <origin xyz="0.00028533 -0.1371 0.01295" rpy="0 0 0" />
    <parent link="L_hand_base_link" />
    <child link="L_middle_proximal" />
    <axis xyz="0 0 -1" />
    <limit lower="0" upper="1.7" effort="1" velocity="0.5" />
  </joint>
  <link name="L_middle_intermediate">
    <inertial>
      <origin xyz="0.001921 -0.020796 -0.0049999" rpy="0 0 0" />
      <mass value="0.0050397" />
      <inertia ixx="9.5823E-07" ixy="-1.1425E-07" ixz="-2.4186E-12" iyy="1.0646E-07" iyz="3.6974E-12" izz="9.8385E-07" />
    </inertial>
    </link>
  <joint name="L_middle_intermediate_joint" type="revolute">
    <origin xyz="-0.0024229 -0.032041 -0.001" rpy="0 0 0" />
    <parent link="L_middle_proximal" />
    <child link="L_middle_intermediate" />
    <axis xyz="0 0 -1" />
    <limit lower="0" upper="1.7" effort="1" velocity="0.5" />
    <mimic joint="L_middle_proximal_joint" multiplier="1" offset="0" />
  </joint>
  <link name="L_ring_proximal">
    <inertial>
      <origin xyz="0.0012971 -0.011934 -0.0059999" rpy="0 0 0" />
      <mass value="0.0042405" />
      <inertia ixx="6.6215E-07" ixy="1.8442E-08" ixz="9.6052E-13" iyy="2.1167E-07" iyz="-1.4124E-11" izz="6.9402E-07" />
    </inertial>
    </link>
  <joint name="L_ring_proximal_joint" type="revolute">
    <origin xyz="0.00028533 -0.13691 -0.0062872" rpy="0.05236 0 0" />
    <parent link="L_hand_base_link" />
    <child link="L_ring_proximal" />
    <axis xyz="0 0 -1" />
    <limit lower="0" upper="1.7" effort="1" velocity="0.5" />
  </joint>
  <link name="L_ring_intermediate">
    <inertial>
      <origin xyz="0.0021753 -0.019567 -0.005" rpy="0 0 0" />
      <mass value="0.0045682" />
      <inertia ixx="7.6285E-07" ixy="-8.0631E-08" ixz="3.3472E-14" iyy="9.4308E-08" iyz="-4.4773E-13" izz="7.8176E-07" />
    </inertial>
    </link>
  <joint name="L_ring_intermediate_joint" type="revolute">
    <origin xyz="-0.0024229 -0.032041 -0.001" rpy="0 0 0" />
    <parent link="L_ring_proximal" />
    <child link="L_ring_intermediate" />
    <axis xyz="0 0 -1" />
    <limit lower="0" upper="1.7" effort="1" velocity="0.5" />
    <mimic joint="L_ring_proximal_joint" multiplier="1" offset="0" />
  </joint>
  <link name="L_pinky_proximal">
    <inertial>
      <origin xyz="0.0012971 -0.011934 -0.0059999" rpy="0 0 0" />
      <mass value="0.0042405" />
      <inertia ixx="6.6215E-07" ixy="1.8442E-08" ixz="1.0279E-12" iyy="2.1167E-07" iyz="-1.4277E-11" izz="6.9402E-07" />
    </inertial>
    </link>
  <joint name="L_pinky_proximal_joint" type="revolute">
    <origin xyz="0.00028533 -0.13571 -0.025488" rpy="0.10472 0 0" />
    <parent link="L_hand_base_link" />
    <child link="L_pinky_proximal" />
    <axis xyz="0 0 -1" />
    <limit lower="0" upper="1.7" effort="1" velocity="0.5" />
  </joint>
  <link name="L_pinky_intermediate">
    <inertial>
      <origin xyz="0.0024788 -0.016208 -0.0050001" rpy="0 0 0" />
      <mass value="0.0036036" />
      <inertia ixx="4.3923E-07" ixy="-4.1355E-08" ixz="1.2263E-12" iyy="7.0315E-08" iyz="3.1311E-12" izz="4.4881E-07" />
    </inertial>
    </link>
  <joint name="L_pinky_intermediate_joint" type="revolute">
    <origin xyz="-0.0024229 -0.032041 -0.001" rpy="0 0 0" />
    <parent link="L_pinky_proximal" />
    <child link="L_pinky_intermediate" />
    <axis xyz="0 0 -1" />
    <limit lower="0" upper="1.7" effort="1" velocity="0.5" />
    <mimic joint="L_pinky_proximal_joint" multiplier="1" offset="0" />
  </joint>

  <!-- R Gripper -->
  <joint name="R_base_link_joint" type="fixed">
    <origin xyz="0.054 0 0" rpy="3.1415926535897932384626433832795 0 -1.5707963267948966192313216916398" />
    <parent link="right_wrist_yaw_link" />
    <child link="R_hand_base_link" />
  </joint>
  <link name="R_hand_base_link">
    <inertial>
      <origin xyz="-0.0025264 -0.066047 0.0019598" rpy="0 0 0" />
      <mass value="0.14143" />
      <inertia ixx="0.00012281" ixy="2.1711E-06" ixz="1.7709E-06" iyy="8.3832E-05" iyz="-1.6551E-06" izz="7.6663E-05" />
    </inertial>
    </link>
  <link name="R_thumb_proximal_base">
    <inertial>
      <origin xyz="-0.0048064 0.0009382 -0.00757" rpy="0 0 0" />
      <mass value="0.0018869" />
      <inertia ixx="5.816E-08" ixy="1.4539E-08" ixz="4.491E-09" iyy="7.9161E-08" iyz="-1.8727E-09" izz="6.7433E-08" />
    </inertial>
    </link>
  <joint name="R_thumb_proximal_yaw_joint" type="revolute">
    <origin xyz="-0.01696 -0.0691 -0.02045" rpy="1.5708 -1.5708 0" />
    <parent link="R_hand_base_link" />
    <child link="R_thumb_proximal_base" />
    <axis xyz="0 0 -1" />
    <limit lower="-0.1" upper="1.3" effort="1" velocity="0.5" />
  </joint>
  <link name="R_thumb_proximal">
    <inertial>
      <origin xyz="0.021932 0.012785 -0.0080386" rpy="0 0 0" />
      <mass value="0.0066075" />
      <inertia ixx="1.5686E-06" ixy="-7.8296E-07" ixz="8.9143E-10" iyy="1.7353E-06" iyz="-1.0191E-09" izz="2.786E-06" />
    </inertial>
    </link>
  <joint name="R_thumb_proximal_pitch_joint" type="revolute">
    <origin xyz="-0.0088099 0.010892 -0.00925" rpy="1.5708 0 2.8587" />
    <parent link="R_thumb_proximal_base" />
    <child link="R_thumb_proximal" />
    <axis xyz="0 0 1" />
    <limit lower="-0.1" upper="0.6" effort="1" velocity="0.5" />
  </joint>
  <link name="R_thumb_intermediate">
    <inertial>
      <origin xyz="0.0095544 -0.0016282 -0.0071997" rpy="0 0 0" />
      <mass value="0.0037847" />
      <inertia ixx="3.6981E-07" ixy="-9.8581E-08" ixz="-4.7469E-12" iyy="3.2394E-07" iyz="1.0939E-12" izz="4.6531E-07" />
    </inertial>
    </link>
  <joint name="R_thumb_intermediate_joint" type="revolute">
    <origin xyz="0.04407 0.034553 -0.0008" rpy="0 0 0" />
    <parent link="R_thumb_proximal" />
    <child link="R_thumb_intermediate" />
    <axis xyz="0 0 1" />
    <limit lower="0" upper="0.8" effort="1" velocity="0.5" />
    <mimic joint="R_thumb_proximal_pitch_joint" multiplier="1.6" offset="0" />
  </joint>
  <link name="R_thumb_distal">
    <inertial>
      <origin xyz="0.0092888 0.0049529 -0.0060033" rpy="0 0 0" />
      <mass value="0.0033441" />
      <inertia ixx="1.3632E-07" ixy="-5.6788E-08" ixz="-9.2764E-11" iyy="1.4052E-07" iyz="-1.2283E-10" izz="2.0026E-07" />
    </inertial>
    </link>
  <joint name="R_thumb_distal_joint" type="revolute">
    <origin xyz="0.020248 0.010156 -0.0012" rpy="0 0 0" />
    <parent link="R_thumb_intermediate" />
    <child link="R_thumb_distal" />
    <axis xyz="0 0 1" />
    <limit lower="0" upper="1.2" effort="1" velocity="0.5" />
    <mimic joint="R_thumb_proximal_pitch_joint" multiplier="2.4" offset="0" />
  </joint>
  <link name="R_index_proximal">
    <inertial>
      <origin xyz="0.0012259 0.011942 -0.0060001" rpy="0 0 0" />
      <mass value="0.0042403" />
      <inertia ixx="6.6232E-07" ixy="-1.5775E-08" ixz="1.8515E-12" iyy="2.1146E-07" iyz="-5.0828E-12" izz="6.9398E-07" />
    </inertial>
    </link>
  <joint name="R_index_proximal_joint" type="revolute">
    <origin xyz="0.00028533 -0.13653 -0.032268" rpy="-3.1067 0 0" />
    <parent link="R_hand_base_link" />
    <child link="R_index_proximal" />
    <axis xyz="0 0 1" />
    <limit lower="0" upper="1.7" effort="1" velocity="0.5" />
  </joint>
  <link name="R_index_intermediate">
    <inertial>
      <origin xyz="0.0019697 0.019589 -0.005" rpy="0 0 0" />
      <mass value="0.0045683" />
      <inertia ixx="7.6111E-07" ixy="8.7637E-08" ixz="-3.7751E-13" iyy="9.6076E-08" iyz="9.9444E-13" izz="7.8179E-07" />
    </inertial>
    </link>
  <joint name="R_index_intermediate_joint" type="revolute">
    <origin xyz="-0.0026138 0.032026 -0.001" rpy="0 0 0" />
    <parent link="R_index_proximal" />
    <child link="R_index_intermediate" />
    <axis xyz="0 0 1" />
    <limit lower="0" upper="1.7" effort="1" velocity="0.5" />
    <mimic joint="R_index_proximal_joint" multiplier="1" offset="0" />
  </joint>
  <link name="R_middle_proximal">
    <inertial>
      <origin xyz="0.001297 0.011934 -0.0060001" rpy="0 0 0" />
      <mass value="0.0042403" />
      <inertia ixx="6.6211E-07" ixy="-1.8461E-08" ixz="1.8002E-12" iyy="2.1167E-07" iyz="-6.6808E-12" izz="6.9397E-07" />
    </inertial>
    </link>
  <joint name="R_middle_proximal_joint" type="revolute">
    <origin xyz="0.00028533 -0.1371 -0.01295" rpy="-3.1416 0 0" />
    <parent link="R_hand_base_link" />
    <child link="R_middle_proximal" />
    <axis xyz="0 0 1" />
    <limit lower="0" upper="1.7" effort="1" velocity="0.5" />
  </joint>
  <link name="R_middle_intermediate">
    <inertial>
      <origin xyz="0.001921 0.020796 -0.005" rpy="0 0 0" />
      <mass value="0.0050396" />
      <inertia ixx="9.5822E-07" ixy="1.1425E-07" ixz="-2.4791E-12" iyy="1.0646E-07" iyz="5.9173E-12" izz="9.8384E-07" />
    </inertial>
    </link>
  <joint name="R_middle_intermediate_joint" type="revolute">
    <origin xyz="-0.0024229 0.032041 -0.001" rpy="0 0 0" />
    <parent link="R_middle_proximal" />
    <child link="R_middle_intermediate" />
    <axis xyz="0 0 1" />
    <limit lower="0" upper="1.7" effort="1" velocity="0.5" />
    <mimic joint="R_middle_proximal_joint" multiplier="1" offset="0" />
  </joint>
  <link name="R_ring_proximal">
    <inertial>
      <origin xyz="0.001297 0.011934 -0.0060002" rpy="0 0 0" />
      <mass value="0.0042403" />
      <inertia ixx="6.6211E-07" ixy="-1.8461E-08" ixz="1.5793E-12" iyy="2.1167E-07" iyz="-6.6868E-12" izz="6.9397E-07" />
    </inertial>
    </link>
  <joint name="R_ring_proximal_joint" type="revolute">
    <origin xyz="0.00028533 -0.13691 0.0062872" rpy="3.0892 0 0" />
    <parent link="R_hand_base_link" />
    <child link="R_ring_proximal" />
    <axis xyz="0 0 1" />
    <limit lower="0" upper="1.7" effort="1" velocity="0.5" />
  </joint>
  <link name="R_ring_intermediate">
    <inertial>
      <origin xyz="0.0021753 0.019567 -0.005" rpy="0 0 0" />
      <mass value="0.0045683" />
      <inertia ixx="7.6286E-07" ixy="8.0635E-08" ixz="-6.1562E-13" iyy="9.431E-08" iyz="5.8619E-13" izz="7.8177E-07" />
    </inertial>
    </link>
  <joint name="R_ring_intermediate_joint" type="revolute">
    <origin xyz="-0.0024229 0.032041 -0.001" rpy="0 0 0" />
    <parent link="R_ring_proximal" />
    <child link="R_ring_intermediate" />
    <axis xyz="0 0 1" />
    <limit lower="0" upper="1.7" effort="1" velocity="0.5" />
    <mimic joint="R_ring_proximal_joint" multiplier="1" offset="0" />
  </joint>
  <link name="R_pinky_proximal">
    <inertial>
      <origin xyz="0.001297 0.011934 -0.0060001" rpy="0 0 0" />
      <mass value="0.0042403" />
      <inertia ixx="6.6211E-07" ixy="-1.8461E-08" ixz="1.6907E-12" iyy="2.1167E-07" iyz="-6.9334E-12" izz="6.9397E-07" />
    </inertial>
    </link>
  <joint name="R_pinky_proximal_joint" type="revolute">
    <origin xyz="0.00028533 -0.13571 0.025488" rpy="3.0369 0 0" />
    <parent link="R_hand_base_link" />
    <child link="R_pinky_proximal" />
    <axis xyz="0 0 1" />
    <limit lower="0" upper="1.7" effort="1" velocity="0.5" />
  </joint>
  <link name="R_pinky_intermediate">
    <inertial>
      <origin xyz="0.0024748 0.016203 -0.0050031" rpy="0 0 0" />
      <mass value="0.0035996" />
      <inertia ixx="4.3913E-07" ixy="4.1418E-08" ixz="3.7168E-11" iyy="7.0247E-08" iyz="5.8613E-11" izz="4.4867E-07" />
    </inertial>
    </link>
  <joint name="R_pinky_intermediate_joint" type="revolute">
    <origin xyz="-0.0024229 0.032041 -0.001" rpy="0 0 0" />
    <parent link="R_pinky_proximal" />
    <child link="R_pinky_intermediate" />
    <axis xyz="0 0 1" />
    <limit lower="0" upper="1.7" effort="1" velocity="0.5" />
    <mimic joint="R_pinky_proximal_joint" multiplier="1" offset="0" />
  </joint>
<link name="pelvis_sphere1"><inertial><origin xyz="0 0 0" rpy="0 0 0" /><mass value="0.01" /><inertia ixx="0.001" ixy="0" ixz="0" iyy="0.001" iyz="0" izz="0.001" /></inertial><visual><origin rpy="0 0 0" xyz="0 0 0" /><geometry><sphere radius="0.0566188208758831" /></geometry><material name="color_pelvis_sphere1_0"><color rgba="0.9 0.1 0.1 1.0" /></material></visual><collision><origin rpy="0 0 0" xyz="0 0 0" /><geometry><sphere radius="0.0566188208758831" /></geometry><drake:proximity_properties><drake:rigid_hydroelastic /><drake:mesh_resolution_hint value="1.5" /><drake:hunt_crossley_dissipation value="1.25" /></drake:proximity_properties></collision></link><joint name="pelvis_to_pelvis_sphere1" type="fixed"><parent link="pelvis" /><child link="pelvis_sphere1" /><origin xyz="-0.0006582838832400739 -0.09225943684577942 -0.042492982000112534" rpy="0 0 0" /></joint><link name="pelvis_sphere2"><inertial><origin xyz="0 0 0" rpy="0 0 0" /><mass value="0.01" /><inertia ixx="0.001" ixy="0" ixz="0" iyy="0.001" iyz="0" izz="0.001" /></inertial><visual><origin rpy="0 0 0" xyz="0 0 0" /><geometry><sphere radius="0.05338418856263161" /></geometry><material name="color_pelvis_sphere2_0"><color rgba="0.9 0.1 0.1 1.0" /></material></visual><collision><origin rpy="0 0 0" xyz="0 0 0" /><geometry><sphere radius="0.05338418856263161" /></geometry><drake:proximity_properties><drake:rigid_hydroelastic /><drake:mesh_resolution_hint value="1.5" /><drake:hunt_crossley_dissipation value="1.25" /></drake:proximity_properties></collision></link><joint name="pelvis_to_pelvis_sphere2" type="fixed"><parent link="pelvis" /><child link="pelvis_sphere2" /><origin xyz="0.022457826882600784 -0.0023631195072084665 -0.03878297284245491" rpy="0 0 0" /></joint><link name="pelvis_sphere3"><inertial><origin xyz="0 0 0" rpy="0 0 0" /><mass value="0.01" /><inertia ixx="0.001" ixy="0" ixz="0" iyy="0.001" iyz="0" izz="0.001" /></inertial><visual><origin rpy="0 0 0" xyz="0 0 0" /><geometry><sphere radius="0.05706167593598366" /></geometry><material name="color_pelvis_sphere3_0"><color rgba="0.9 0.1 0.1 1.0" /></material></visual><collision><origin rpy="0 0 0" xyz="0 0 0" /><geometry><sphere radius="0.05706167593598366" /></geometry><drake:proximity_properties><drake:rigid_hydroelastic /><drake:mesh_resolution_hint value="1.5" /><drake:hunt_crossley_dissipation value="1.25" /></drake:proximity_properties></collision></link><joint name="pelvis_to_pelvis_sphere3" type="fixed"><parent link="pelvis" /><child link="pelvis_sphere3" /><origin xyz="0.00048275734297931194 0.09225258976221085 -0.0420948825776577" rpy="0 0 0" /></joint><link name="pelvis_sphere4"><inertial><origin xyz="0 0 0" rpy="0 0 0" /><mass value="0.01" /><inertia ixx="0.001" ixy="0" ixz="0" iyy="0.001" iyz="0" izz="0.001" /></inertial><visual><origin rpy="0 0 0" xyz="0 0 0" /><geometry><sphere radius="0.05298854783177376" /></geometry><material name="color_pelvis_sphere4_0"><color rgba="0.9 0.1 0.1 1.0" /></material></visual><collision><origin rpy="0 0 0" xyz="0 0 0" /><geometry><sphere radius="0.05298854783177376" /></geometry><drake:proximity_properties><drake:rigid_hydroelastic /><drake:mesh_resolution_hint value="1.5" /><drake:hunt_crossley_dissipation value="1.25" /></drake:proximity_properties></collision></link><joint name="pelvis_to_pelvis_sphere4" type="fixed"><parent link="pelvis" /><child link="pelvis_sphere4" /><origin xyz="-0.02288988046348095 0.0027171848341822624 -0.03924413025379181" rpy="0 0 0" /></joint><link name="torso_link_sphere1"><inertial><origin xyz="0 0 0" rpy="0 0 0" /><mass value="0.01" /><inertia ixx="0.001" ixy="0" ixz="0" iyy="0.001" iyz="0" izz="0.001" /></inertial><visual><origin rpy="0 0 0" xyz="0 0 0" /><geometry><sphere radius="0.11691099405288696" /></geometry><material name="color_torso_link_sphere1_0"><color rgba="0.8 0.3 0.2 1.0" /></material></visual><collision><origin rpy="0 0 0" xyz="0 0 0" /><geometry><sphere radius="0.11691099405288696" /></geometry><drake:proximity_properties><drake:rigid_hydroelastic /><drake:mesh_resolution_hint value="1.5" /><drake:hunt_crossley_dissipation value="1.25" /></drake:proximity_properties></collision></link><joint name="torso_link_to_torso_link_sphere1" type="fixed"><parent link="torso_link" /><child link="torso_link_sphere1" /><origin xyz="0.010826588608324528 -0.0009171374840661883 0.28240811824798584" rpy="0 0 0" /></joint><link name="torso_link_sphere2"><inertial><origin xyz="0 0 0" rpy="0 0 0" /><mass value="0.01" /><inertia ixx="0.001" ixy="0" ixz="0" iyy="0.001" iyz="0" izz="0.001" /></inertial><visual><origin rpy="0 0 0" xyz="0 0 0" /><geometry><sphere radius="0.08996040374040604" /></geometry><material name="color_torso_link_sphere2_0"><color rgba="0.8 0.3 0.2 1.0" /></material></visual><collision><origin rpy="0 0 0" xyz="0 0 0" /><geometry><sphere radius="0.08996040374040604" /></geometry><drake:proximity_properties><drake:rigid_hydroelastic /><drake:mesh_resolution_hint value="1.5" /><drake:hunt_crossley_dissipation value="1.25" /></drake:proximity_properties></collision></link><joint name="torso_link_to_torso_link_sphere2" type="fixed"><parent link="torso_link" /><child link="torso_link_sphere2" /><origin xyz="0.04552965238690376 0.00036791275488212705 0.669076681137085" rpy="0 0 0" /></joint><link name="torso_link_sphere3"><inertial><origin xyz="0 0 0" rpy="0 0 0" /><mass value="0.01" /><inertia ixx="0.001" ixy="0" ixz="0" iyy="0.001" iyz="0" izz="0.001" /></inertial><visual><origin rpy="0 0 0" xyz="0 0 0" /><geometry><sphere radius="0.10513805598020554" /></geometry><material name="color_torso_link_sphere3_0"><color rgba="0.8 0.3 0.2 1.0" /></material></visual><collision><origin rpy="0 0 0" xyz="0 0 0" /><geometry><sphere radius="0.10513805598020554" /></geometry><drake:proximity_properties><drake:rigid_hydroelastic /><drake:mesh_resolution_hint value="1.5" /><drake:hunt_crossley_dissipation value="1.25" /></drake:proximity_properties></collision></link><joint name="torso_link_to_torso_link_sphere3" type="fixed"><parent link="torso_link" /><child link="torso_link_sphere3" /><origin xyz="0.003146003931760788 0.0014351505087688565 0.08999927341938019" rpy="0 0 0" /></joint><link name="torso_link_sphere4"><inertial><origin xyz="0 0 0" rpy="0 0 0" /><mass value="0.01" /><inertia ixx="0.001" ixy="0" ixz="0" iyy="0.001" iyz="0" izz="0.001" /></inertial><visual><origin rpy="0 0 0" xyz="0 0 0" /><geometry><sphere radius="0.11523880064487457" /></geometry><material name="color_torso_link_sphere4_0"><color rgba="0.8 0.3 0.2 1.0" /></material></visual><collision><origin rpy="0 0 0" xyz="0 0 0" /><geometry><sphere radius="0.11523880064487457" /></geometry><drake:proximity_properties><drake:rigid_hydroelastic /><drake:mesh_resolution_hint value="1.5" /><drake:hunt_crossley_dissipation value="1.25" /></drake:proximity_properties></collision></link><joint name="torso_link_to_torso_link_sphere4" type="fixed"><parent link="torso_link" /><child link="torso_link_sphere4" /><origin xyz="0.01870313659310341 0.00013361524906940758 0.5028911232948303" rpy="0 0 0" /></joint><link name="left_shoulder_pitch_link_sphere1"><inertial><origin xyz="0 0 0" rpy="0 0 0" /><mass value="0.01" /><inertia ixx="0.001" ixy="0" ixz="0" iyy="0.001" iyz="0" izz="0.001" /></inertial><visual><origin rpy="0 0 0" xyz="0 0 0" /><geometry><sphere radius="0.04007035866379738" /></geometry><material name="color_left_shoulder_pitch_link_sphere1_0"><color rgba="0.9 0.9 0.1 1.0" /></material></visual><collision><origin rpy="0 0 0" xyz="0 0 0" /><geometry><sphere radius="0.04007035866379738" /></geometry><drake:proximity_properties><drake:rigid_hydroelastic /><drake:mesh_resolution_hint value="1.5" /><drake:hunt_crossley_dissipation value="1.25" /></drake:proximity_properties></collision></link><joint name="left_shoulder_pitch_link_to_left_shoulder_pitch_link_sphere1" type="fixed"><parent link="left_shoulder_pitch_link" /><child link="left_shoulder_pitch_link_sphere1" /><origin xyz="-0.0055639115162193775 0.028533393517136574 -0.0015987249789759517" rpy="0 0 0" /></joint><link name="left_shoulder_pitch_link_sphere2"><inertial><origin xyz="0 0 0" rpy="0 0 0" /><mass value="0.01" /><inertia ixx="0.001" ixy="0" ixz="0" iyy="0.001" iyz="0" izz="0.001" /></inertial><visual><origin rpy="0 0 0" xyz="0 0 0" /><geometry><sphere radius="0.04713156074285507" /></geometry><material name="color_left_shoulder_pitch_link_sphere2_0"><color rgba="0.9 0.9 0.1 1.0" /></material></visual><collision><origin rpy="0 0 0" xyz="0 0 0" /><geometry><sphere radius="0.04713156074285507" /></geometry><drake:proximity_properties><drake:rigid_hydroelastic /><drake:mesh_resolution_hint value="1.5" /><drake:hunt_crossley_dissipation value="1.25" /></drake:proximity_properties></collision></link><joint name="left_shoulder_pitch_link_to_left_shoulder_pitch_link_sphere2" type="fixed"><parent link="left_shoulder_pitch_link" /><child link="left_shoulder_pitch_link_sphere2" /><origin xyz="-0.0035407014656811953 0.0644945427775383 -0.006427110638469458" rpy="0 0 0" /></joint><link name="left_shoulder_roll_link_sphere1"><inertial><origin xyz="0 0 0" rpy="0 0 0" /><mass value="0.01" /><inertia ixx="0.001" ixy="0" ixz="0" iyy="0.001" iyz="0" izz="0.001" /></inertial><visual><origin rpy="0 0 0" xyz="0 0 0" /><geometry><sphere radius="0.05052065849304199" /></geometry><material name="color_left_shoulder_roll_link_sphere1_0"><color rgba="0.8 0.8 0.2 1.0" /></material></visual><collision><origin rpy="0 0 0" xyz="0 0 0" /><geometry><sphere radius="0.05052065849304199" /></geometry><drake:proximity_properties><drake:rigid_hydroelastic /><drake:mesh_resolution_hint value="1.5" /><drake:hunt_crossley_dissipation value="1.25" /></drake:proximity_properties></collision></link><joint name="left_shoulder_roll_link_to_left_shoulder_roll_link_sphere1" type="fixed"><parent link="left_shoulder_roll_link" /><child link="left_shoulder_roll_link_sphere1" /><origin xyz="-0.033315472304821014 5.575252362177707e-05 -0.10345423966646194" rpy="0 0 0" /></joint><link name="left_shoulder_roll_link_sphere2"><inertial><origin xyz="0 0 0" rpy="0 0 0" /><mass value="0.01" /><inertia ixx="0.001" ixy="0" ixz="0" iyy="0.001" iyz="0" izz="0.001" /></inertial><visual><origin rpy="0 0 0" xyz="0 0 0" /><geometry><sphere radius="0.044987622648477554" /></geometry><material name="color_left_shoulder_roll_link_sphere2_0"><color rgba="0.8 0.8 0.2 1.0" /></material></visual><collision><origin rpy="0 0 0" xyz="0 0 0" /><geometry><sphere radius="0.044987622648477554" /></geometry><drake:proximity_properties><drake:rigid_hydroelastic /><drake:mesh_resolution_hint value="1.5" /><drake:hunt_crossley_dissipation value="1.25" /></drake:proximity_properties></collision></link><joint name="left_shoulder_roll_link_to_left_shoulder_roll_link_sphere2" type="fixed"><parent link="left_shoulder_roll_link" /><child link="left_shoulder_roll_link_sphere2" /><origin xyz="-0.02272084914147854 -0.00047888094559311867 -0.05580655485391617" rpy="0 0 0" /></joint><link name="left_shoulder_roll_link_sphere3"><inertial><origin xyz="0 0 0" rpy="0 0 0" /><mass value="0.01" /><inertia ixx="0.001" ixy="0" ixz="0" iyy="0.001" iyz="0" izz="0.001" /></inertial><visual><origin rpy="0 0 0" xyz="0 0 0" /><geometry><sphere radius="0.034191690385341644" /></geometry><material name="color_left_shoulder_roll_link_sphere3_0"><color rgba="0.8 0.8 0.2 1.0" /></material></visual><collision><origin rpy="0 0 0" xyz="0 0 0" /><geometry><sphere radius="0.034191690385341644" /></geometry><drake:proximity_properties><drake:rigid_hydroelastic /><drake:mesh_resolution_hint value="1.5" /><drake:hunt_crossley_dissipation value="1.25" /></drake:proximity_properties></collision></link><joint name="left_shoulder_roll_link_to_left_shoulder_roll_link_sphere3" type="fixed"><parent link="left_shoulder_roll_link" /><child link="left_shoulder_roll_link_sphere3" /><origin xyz="-0.007927373982965946 0.000928285822737962 0.004922138527035713" rpy="0 0 0" /></joint><link name="left_shoulder_yaw_link_sphere1"><inertial><origin xyz="0 0 0" rpy="0 0 0" /><mass value="0.01" /><inertia ixx="0.001" ixy="0" ixz="0" iyy="0.001" iyz="0" izz="0.001" /></inertial><visual><origin rpy="0 0 0" xyz="0 0 0" /><geometry><sphere radius="0.0482114776968956" /></geometry><material name="color_left_shoulder_yaw_link_sphere1_0"><color rgba="0.7 0.7 0.3 1.0" /></material></visual><collision><origin rpy="0 0 0" xyz="0 0 0" /><geometry><sphere radius="0.0482114776968956" /></geometry><drake:proximity_properties><drake:rigid_hydroelastic /><drake:mesh_resolution_hint value="1.5" /><drake:hunt_crossley_dissipation value="1.25" /></drake:proximity_properties></collision></link><joint name="left_shoulder_yaw_link_to_left_shoulder_yaw_link_sphere1" type="fixed"><parent link="left_shoulder_yaw_link" /><child link="left_shoulder_yaw_link_sphere1" /><origin xyz="0.0035144169814884663 -0.0029549517203122377 -0.10757333040237427" rpy="0 0 0" /></joint><link name="left_shoulder_yaw_link_sphere2"><inertial><origin xyz="0 0 0" rpy="0 0 0" /><mass value="0.01" /><inertia ixx="0.001" ixy="0" ixz="0" iyy="0.001" iyz="0" izz="0.001" /></inertial><visual><origin rpy="0 0 0" xyz="0 0 0" /><geometry><sphere radius="0.04905075579881668" /></geometry><material name="color_left_shoulder_yaw_link_sphere2_0"><color rgba="0.7 0.7 0.3 1.0" /></material></visual><collision><origin rpy="0 0 0" xyz="0 0 0" /><geometry><sphere radius="0.04905075579881668" /></geometry><drake:proximity_properties><drake:rigid_hydroelastic /><drake:mesh_resolution_hint value="1.5" /><drake:hunt_crossley_dissipation value="1.25" /></drake:proximity_properties></collision></link><joint name="left_shoulder_yaw_link_to_left_shoulder_yaw_link_sphere2" type="fixed"><parent link="left_shoulder_yaw_link" /><child link="left_shoulder_yaw_link_sphere2" /><origin xyz="0.005998233333230019 -0.004742587450891733 -0.18255189061164856" rpy="0 0 0" /></joint><link name="left_shoulder_yaw_link_sphere3"><inertial><origin xyz="0 0 0" rpy="0 0 0" /><mass value="0.01" /><inertia ixx="0.001" ixy="0" ixz="0" iyy="0.001" iyz="0" izz="0.001" /></inertial><visual><origin rpy="0 0 0" xyz="0 0 0" /><geometry><sphere radius="0.046131476759910583" /></geometry><material name="color_left_shoulder_yaw_link_sphere3_0"><color rgba="0.7 0.7 0.3 1.0" /></material></visual><collision><origin rpy="0 0 0" xyz="0 0 0" /><geometry><sphere radius="0.046131476759910583" /></geometry><drake:proximity_properties><drake:rigid_hydroelastic /><drake:mesh_resolution_hint value="1.5" /><drake:hunt_crossley_dissipation value="1.25" /></drake:proximity_properties></collision></link><joint name="left_shoulder_yaw_link_to_left_shoulder_yaw_link_sphere3" type="fixed"><parent link="left_shoulder_yaw_link" /><child link="left_shoulder_yaw_link_sphere3" /><origin xyz="0.001072406186722219 -0.001040010480210185 -0.03502980247139931" rpy="0 0 0" /></joint><link name="left_elbow_link_sphere1"><inertial><origin xyz="0 0 0" rpy="0 0 0" /><mass value="0.01" /><inertia ixx="0.001" ixy="0" ixz="0" iyy="0.001" iyz="0" izz="0.001" /></inertial><visual><origin rpy="0 0 0" xyz="0 0 0" /><geometry><sphere radius="0.037507180124521255" /></geometry><material name="color_left_elbow_link_sphere1_0"><color rgba="0.6 0.6 0.4 1.0" /></material></visual><collision><origin rpy="0 0 0" xyz="0 0 0" /><geometry><sphere radius="0.037507180124521255" /></geometry><drake:proximity_properties><drake:rigid_hydroelastic /><drake:mesh_resolution_hint value="1.5" /><drake:hunt_crossley_dissipation value="1.25" /></drake:proximity_properties></collision></link><joint name="left_elbow_link_to_left_elbow_link_sphere1" type="fixed"><parent link="left_elbow_link" /><child link="left_elbow_link_sphere1" /><origin xyz="0.007809750270098448 -0.01377662643790245 -0.0014792100992053747" rpy="0 0 0" /></joint><link name="left_elbow_link_sphere2"><inertial><origin xyz="0 0 0" rpy="0 0 0" /><mass value="0.01" /><inertia ixx="0.001" ixy="0" ixz="0" iyy="0.001" iyz="0" izz="0.001" /></inertial><visual><origin rpy="0 0 0" xyz="0 0 0" /><geometry><sphere radius="0.041219551116228104" /></geometry><material name="color_left_elbow_link_sphere2_0"><color rgba="0.6 0.6 0.4 1.0" /></material></visual><collision><origin rpy="0 0 0" xyz="0 0 0" /><geometry><sphere radius="0.041219551116228104" /></geometry><drake:proximity_properties><drake:rigid_hydroelastic /><drake:mesh_resolution_hint value="1.5" /><drake:hunt_crossley_dissipation value="1.25" /></drake:proximity_properties></collision></link><joint name="left_elbow_link_to_left_elbow_link_sphere2" type="fixed"><parent link="left_elbow_link" /><child link="left_elbow_link_sphere2" /><origin xyz="0.08422185480594635 -0.03099263645708561 -0.00934826210141182" rpy="0 0 0" /></joint><link name="left_wrist_roll_link_sphere1"><inertial><origin xyz="0 0 0" rpy="0 0 0" /><mass value="0.01" /><inertia ixx="0.001" ixy="0" ixz="0" iyy="0.001" iyz="0" izz="0.001" /></inertial><visual><origin rpy="0 0 0" xyz="0 0 0" /><geometry><sphere radius="0.037074264138936996" /></geometry><material name="color_left_wrist_roll_link_sphere1_0"><color rgba="0.5 0.5 0.5 1.0" /></material></visual><collision><origin rpy="0 0 0" xyz="0 0 0" /><geometry><sphere radius="0.037074264138936996" /></geometry><drake:proximity_properties><drake:rigid_hydroelastic /><drake:mesh_resolution_hint value="1.5" /><drake:hunt_crossley_dissipation value="1.25" /></drake:proximity_properties></collision></link><joint name="left_wrist_roll_link_to_left_wrist_roll_link_sphere1" type="fixed"><parent link="left_wrist_roll_link" /><child link="left_wrist_roll_link_sphere1" /><origin xyz="0.059633299708366394 -0.0010294107487425208 -0.00014918038505129516" rpy="0 0 0" /></joint><link name="left_wrist_roll_link_sphere2"><inertial><origin xyz="0 0 0" rpy="0 0 0" /><mass value="0.01" /><inertia ixx="0.001" ixy="0" ixz="0" iyy="0.001" iyz="0" izz="0.001" /></inertial><visual><origin rpy="0 0 0" xyz="0 0 0" /><geometry><sphere radius="0.040021222084760666" /></geometry><material name="color_left_wrist_roll_link_sphere2_0"><color rgba="0.5 0.5 0.5 1.0" /></material></visual><collision><origin rpy="0 0 0" xyz="0 0 0" /><geometry><sphere radius="0.040021222084760666" /></geometry><drake:proximity_properties><drake:rigid_hydroelastic /><drake:mesh_resolution_hint value="1.5" /><drake:hunt_crossley_dissipation value="1.25" /></drake:proximity_properties></collision></link><joint name="left_wrist_roll_link_to_left_wrist_roll_link_sphere2" type="fixed"><parent link="left_wrist_roll_link" /><child link="left_wrist_roll_link_sphere2" /><origin xyz="0.03263409808278084 -0.0003846439940389246 4.295718554203631e-06" rpy="0 0 0" /></joint><link name="left_wrist_pitch_link_sphere1"><inertial><origin xyz="0 0 0" rpy="0 0 0" /><mass value="0.01" /><inertia ixx="0.001" ixy="0" ixz="0" iyy="0.001" iyz="0" izz="0.001" /></inertial><visual><origin rpy="0 0 0" xyz="0 0 0" /><geometry><sphere radius="0.035843878984451294" /></geometry><material name="color_left_wrist_pitch_link_sphere1_0"><color rgba="0.4 0.4 0.6 1.0" /></material></visual><collision><origin rpy="0 0 0" xyz="0 0 0" /><geometry><sphere radius="0.035843878984451294" /></geometry><drake:proximity_properties><drake:rigid_hydroelastic /><drake:mesh_resolution_hint value="1.5" /><drake:hunt_crossley_dissipation value="1.25" /></drake:proximity_properties></collision></link><joint name="left_wrist_pitch_link_to_left_wrist_pitch_link_sphere1" type="fixed"><parent link="left_wrist_pitch_link" /><child link="left_wrist_pitch_link_sphere1" /><origin xyz="0.019394882023334503 -0.0005386839620769024 0.00023985820007510483" rpy="0 0 0" /></joint><link name="left_wrist_pitch_link_sphere2"><inertial><origin xyz="0 0 0" rpy="0 0 0" /><mass value="0.01" /><inertia ixx="0.001" ixy="0" ixz="0" iyy="0.001" iyz="0" izz="0.001" /></inertial><visual><origin rpy="0 0 0" xyz="0 0 0" /><geometry><sphere radius="0.016445690765976906" /></geometry><material name="color_left_wrist_pitch_link_sphere2_0"><color rgba="0.4 0.4 0.6 1.0" /></material></visual><collision><origin rpy="0 0 0" xyz="0 0 0" /><geometry><sphere radius="0.016445690765976906" /></geometry><drake:proximity_properties><drake:rigid_hydroelastic /><drake:mesh_resolution_hint value="1.5" /><drake:hunt_crossley_dissipation value="1.25" /></drake:proximity_properties></collision></link><joint name="left_wrist_pitch_link_to_left_wrist_pitch_link_sphere2" type="fixed"><parent link="left_wrist_pitch_link" /><child link="left_wrist_pitch_link_sphere2" /><origin xyz="0.007670825347304344 0.01815078593790531 0.015903810039162636" rpy="0 0 0" /></joint><link name="left_wrist_yaw_link_sphere1"><inertial><origin xyz="0 0 0" rpy="0 0 0" /><mass value="0.01" /><inertia ixx="0.001" ixy="0" ixz="0" iyy="0.001" iyz="0" izz="0.001" /></inertial><visual><origin rpy="0 0 0" xyz="0 0 0" /><geometry><sphere radius="0.024296803399920464" /></geometry><material name="color_left_wrist_yaw_link_sphere1_0"><color rgba="0.3 0.3 0.7 1.0" /></material></visual><collision><origin rpy="0 0 0" xyz="0 0 0" /><geometry><sphere radius="0.024296803399920464" /></geometry><drake:proximity_properties><drake:rigid_hydroelastic /><drake:mesh_resolution_hint value="1.5" /><drake:hunt_crossley_dissipation value="1.25" /></drake:proximity_properties></collision></link><joint name="left_wrist_yaw_link_to_left_wrist_yaw_link_sphere1" type="fixed"><parent link="left_wrist_yaw_link" /><child link="left_wrist_yaw_link_sphere1" /><origin xyz="0.00269945221953094 -9.838795085670426e-05 0.02230464667081833" rpy="0 0 0" /></joint><link name="left_wrist_yaw_link_sphere2"><inertial><origin xyz="0 0 0" rpy="0 0 0" /><mass value="0.01" /><inertia ixx="0.001" ixy="0" ixz="0" iyy="0.001" iyz="0" izz="0.001" /></inertial><visual><origin rpy="0 0 0" xyz="0 0 0" /><geometry><sphere radius="0.038393523544073105" /></geometry><material name="color_left_wrist_yaw_link_sphere2_0"><color rgba="0.3 0.3 0.7 1.0" /></material></visual><collision><origin rpy="0 0 0" xyz="0 0 0" /><geometry><sphere radius="0.038393523544073105" /></geometry><drake:proximity_properties><drake:rigid_hydroelastic /><drake:mesh_resolution_hint value="1.5" /><drake:hunt_crossley_dissipation value="1.25" /></drake:proximity_properties></collision></link><joint name="left_wrist_yaw_link_to_left_wrist_yaw_link_sphere2" type="fixed"><parent link="left_wrist_yaw_link" /><child link="left_wrist_yaw_link_sphere2" /><origin xyz="0.026802748441696167 -0.00021777150686830282 -0.0033844613935798407" rpy="0 0 0" /></joint><link name="right_shoulder_pitch_link_sphere1"><inertial><origin xyz="0 0 0" rpy="0 0 0" /><mass value="0.01" /><inertia ixx="0.001" ixy="0" ixz="0" iyy="0.001" iyz="0" izz="0.001" /></inertial><visual><origin rpy="0 0 0" xyz="0 0 0" /><geometry><sphere radius="0.04723702743649483" /></geometry><material name="color_right_shoulder_pitch_link_sphere1_0"><color rgba="0.8 0.2 0.8 1.0" /></material></visual><collision><origin rpy="0 0 0" xyz="0 0 0" /><geometry><sphere radius="0.04723702743649483" /></geometry><drake:proximity_properties><drake:rigid_hydroelastic /><drake:mesh_resolution_hint value="1.5" /><drake:hunt_crossley_dissipation value="1.25" /></drake:proximity_properties></collision></link><joint name="right_shoulder_pitch_link_to_right_shoulder_pitch_link_sphere1" type="fixed"><parent link="right_shoulder_pitch_link" /><child link="right_shoulder_pitch_link_sphere1" /><origin xyz="-0.003680979600176215 -0.06455270946025848 -0.0064382003620266914" rpy="0 0 0" /></joint><link name="right_shoulder_pitch_link_sphere2"><inertial><origin xyz="0 0 0" rpy="0 0 0" /><mass value="0.01" /><inertia ixx="0.001" ixy="0" ixz="0" iyy="0.001" iyz="0" izz="0.001" /></inertial><visual><origin rpy="0 0 0" xyz="0 0 0" /><geometry><sphere radius="0.04002835974097252" /></geometry><material name="color_right_shoulder_pitch_link_sphere2_0"><color rgba="0.8 0.2 0.8 1.0" /></material></visual><collision><origin rpy="0 0 0" xyz="0 0 0" /><geometry><sphere radius="0.04002835974097252" /></geometry><drake:proximity_properties><drake:rigid_hydroelastic /><drake:mesh_resolution_hint value="1.5" /><drake:hunt_crossley_dissipation value="1.25" /></drake:proximity_properties></collision></link><joint name="right_shoulder_pitch_link_to_right_shoulder_pitch_link_sphere2" type="fixed"><parent link="right_shoulder_pitch_link" /><child link="right_shoulder_pitch_link_sphere2" /><origin xyz="-0.005190012510865927 -0.028446298092603683 -0.0013756104744970798" rpy="0 0 0" /></joint><link name="right_shoulder_roll_link_sphere1"><inertial><origin xyz="0 0 0" rpy="0 0 0" /><mass value="0.01" /><inertia ixx="0.001" ixy="0" ixz="0" iyy="0.001" iyz="0" izz="0.001" /></inertial><visual><origin rpy="0 0 0" xyz="0 0 0" /><geometry><sphere radius="0.039658304303884506" /></geometry><material name="color_right_shoulder_roll_link_sphere1_0"><color rgba="0.7 0.3 0.7 1.0" /></material></visual><collision><origin rpy="0 0 0" xyz="0 0 0" /><geometry><sphere radius="0.039658304303884506" /></geometry><drake:proximity_properties><drake:rigid_hydroelastic /><drake:mesh_resolution_hint value="1.5" /><drake:hunt_crossley_dissipation value="1.25" /></drake:proximity_properties></collision></link><joint name="right_shoulder_roll_link_to_right_shoulder_roll_link_sphere1" type="fixed"><parent link="right_shoulder_roll_link" /><child link="right_shoulder_roll_link_sphere1" /><origin xyz="-0.011107245460152626 8.255335706053302e-05 -0.009049780666828156" rpy="0 0 0" /></joint><link name="right_shoulder_roll_link_sphere2"><inertial><origin xyz="0 0 0" rpy="0 0 0" /><mass value="0.01" /><inertia ixx="0.001" ixy="0" ixz="0" iyy="0.001" iyz="0" izz="0.001" /></inertial><visual><origin rpy="0 0 0" xyz="0 0 0" /><geometry><sphere radius="0.051742687821388245" /></geometry><material name="color_right_shoulder_roll_link_sphere2_0"><color rgba="0.7 0.3 0.7 1.0" /></material></visual><collision><origin rpy="0 0 0" xyz="0 0 0" /><geometry><sphere radius="0.051742687821388245" /></geometry><drake:proximity_properties><drake:rigid_hydroelastic /><drake:mesh_resolution_hint value="1.5" /><drake:hunt_crossley_dissipation value="1.25" /></drake:proximity_properties></collision></link><joint name="right_shoulder_roll_link_to_right_shoulder_roll_link_sphere2" type="fixed"><parent link="right_shoulder_roll_link" /><child link="right_shoulder_roll_link_sphere2" /><origin xyz="-0.03162049502134323 -0.00017984892474487424 -0.09812101721763611" rpy="0 0 0" /></joint><link name="right_shoulder_roll_link_sphere3"><inertial><origin xyz="0 0 0" rpy="0 0 0" /><mass value="0.01" /><inertia ixx="0.001" ixy="0" ixz="0" iyy="0.001" iyz="0" izz="0.001" /></inertial><visual><origin rpy="0 0 0" xyz="0 0 0" /><geometry><sphere radius="0.026181429624557495" /></geometry><material name="color_right_shoulder_roll_link_sphere3_0"><color rgba="0.7 0.3 0.7 1.0" /></material></visual><collision><origin rpy="0 0 0" xyz="0 0 0" /><geometry><sphere radius="0.026181429624557495" /></geometry><drake:proximity_properties><drake:rigid_hydroelastic /><drake:mesh_resolution_hint value="1.5" /><drake:hunt_crossley_dissipation value="1.25" /></drake:proximity_properties></collision></link><joint name="right_shoulder_roll_link_to_right_shoulder_roll_link_sphere3" type="fixed"><parent link="right_shoulder_roll_link" /><child link="right_shoulder_roll_link_sphere3" /><origin xyz="-0.0589204840362072 0.002089511137455702 -0.12427430599927902" rpy="0 0 0" /></joint><link name="right_shoulder_yaw_link_sphere1"><inertial><origin xyz="0 0 0" rpy="0 0 0" /><mass value="0.01" /><inertia ixx="0.001" ixy="0" ixz="0" iyy="0.001" iyz="0" izz="0.001" /></inertial><visual><origin rpy="0 0 0" xyz="0 0 0" /><geometry><sphere radius="0.049001093953847885" /></geometry><material name="color_right_shoulder_yaw_link_sphere1_0"><color rgba="0.6 0.4 0.6 1.0" /></material></visual><collision><origin rpy="0 0 0" xyz="0 0 0" /><geometry><sphere radius="0.049001093953847885" /></geometry><drake:proximity_properties><drake:rigid_hydroelastic /><drake:mesh_resolution_hint value="1.5" /><drake:hunt_crossley_dissipation value="1.25" /></drake:proximity_properties></collision></link><joint name="right_shoulder_yaw_link_to_right_shoulder_yaw_link_sphere1" type="fixed"><parent link="right_shoulder_yaw_link" /><child link="right_shoulder_yaw_link_sphere1" /><origin xyz="0.006149510387331247 0.0037196094635874033 -0.1824377328157425" rpy="0 0 0" /></joint><link name="right_shoulder_yaw_link_sphere2"><inertial><origin xyz="0 0 0" rpy="0 0 0" /><mass value="0.01" /><inertia ixx="0.001" ixy="0" ixz="0" iyy="0.001" iyz="0" izz="0.001" /></inertial><visual><origin rpy="0 0 0" xyz="0 0 0" /><geometry><sphere radius="0.04595596343278885" /></geometry><material name="color_right_shoulder_yaw_link_sphere2_0"><color rgba="0.6 0.4 0.6 1.0" /></material></visual><collision><origin rpy="0 0 0" xyz="0 0 0" /><geometry><sphere radius="0.04595596343278885" /></geometry><drake:proximity_properties><drake:rigid_hydroelastic /><drake:mesh_resolution_hint value="1.5" /><drake:hunt_crossley_dissipation value="1.25" /></drake:proximity_properties></collision></link><joint name="right_shoulder_yaw_link_to_right_shoulder_yaw_link_sphere2" type="fixed"><parent link="right_shoulder_yaw_link" /><child link="right_shoulder_yaw_link_sphere2" /><origin xyz="0.0011280515464022756 0.0008468462037853897 -0.03483981639146805" rpy="0 0 0" /></joint><link name="right_shoulder_yaw_link_sphere3"><inertial><origin xyz="0 0 0" rpy="0 0 0" /><mass value="0.01" /><inertia ixx="0.001" ixy="0" ixz="0" iyy="0.001" iyz="0" izz="0.001" /></inertial><visual><origin rpy="0 0 0" xyz="0 0 0" /><geometry><sphere radius="0.048399798572063446" /></geometry><material name="color_right_shoulder_yaw_link_sphere3_0"><color rgba="0.6 0.4 0.6 1.0" /></material></visual><collision><origin rpy="0 0 0" xyz="0 0 0" /><geometry><sphere radius="0.048399798572063446" /></geometry><drake:proximity_properties><drake:rigid_hydroelastic /><drake:mesh_resolution_hint value="1.5" /><drake:hunt_crossley_dissipation value="1.25" /></drake:proximity_properties></collision></link><joint name="right_shoulder_yaw_link_to_right_shoulder_yaw_link_sphere3" type="fixed"><parent link="right_shoulder_yaw_link" /><child link="right_shoulder_yaw_link_sphere3" /><origin xyz="0.0034585162065923214 0.0028140698559582233 -0.10681332647800446" rpy="0 0 0" /></joint><link name="right_elbow_link_sphere1"><inertial><origin xyz="0 0 0" rpy="0 0 0" /><mass value="0.01" /><inertia ixx="0.001" ixy="0" ixz="0" iyy="0.001" iyz="0" izz="0.001" /></inertial><visual><origin rpy="0 0 0" xyz="0 0 0" /><geometry><sphere radius="0.04074307531118393" /></geometry><material name="color_right_elbow_link_sphere1_0"><color rgba="0.5 0.5 0.7 1.0" /></material></visual><collision><origin rpy="0 0 0" xyz="0 0 0" /><geometry><sphere radius="0.04074307531118393" /></geometry><drake:proximity_properties><drake:rigid_hydroelastic /><drake:mesh_resolution_hint value="1.5" /><drake:hunt_crossley_dissipation value="1.25" /></drake:proximity_properties></collision></link><joint name="right_elbow_link_to_right_elbow_link_sphere1" type="fixed"><parent link="right_elbow_link" /><child link="right_elbow_link_sphere1" /><origin xyz="0.085390605032444 0.031085027381777763 -0.009344247169792652" rpy="0 0 0" /></joint><link name="right_elbow_link_sphere2"><inertial><origin xyz="0 0 0" rpy="0 0 0" /><mass value="0.01" /><inertia ixx="0.001" ixy="0" ixz="0" iyy="0.001" iyz="0" izz="0.001" /></inertial><visual><origin rpy="0 0 0" xyz="0 0 0" /><geometry><sphere radius="0.03780282661318779" /></geometry><material name="color_right_elbow_link_sphere2_0"><color rgba="0.5 0.5 0.7 1.0" /></material></visual><collision><origin rpy="0 0 0" xyz="0 0 0" /><geometry><sphere radius="0.03780282661318779" /></geometry><drake:proximity_properties><drake:rigid_hydroelastic /><drake:mesh_resolution_hint value="1.5" /><drake:hunt_crossley_dissipation value="1.25" /></drake:proximity_properties></collision></link><joint name="right_elbow_link_to_right_elbow_link_sphere2" type="fixed"><parent link="right_elbow_link" /><child link="right_elbow_link_sphere2" /><origin xyz="0.009782710112631321 0.014746926724910736 -0.00194728490896523" rpy="0 0 0" /></joint><link name="right_wrist_roll_link_sphere1"><inertial><origin xyz="0 0 0" rpy="0 0 0" /><mass value="0.01" /><inertia ixx="0.001" ixy="0" ixz="0" iyy="0.001" iyz="0" izz="0.001" /></inertial><visual><origin rpy="0 0 0" xyz="0 0 0" /><geometry><sphere radius="0.03964679688215256" /></geometry><material name="color_right_wrist_roll_link_sphere1_0"><color rgba="0.4 0.6 0.8 1.0" /></material></visual><collision><origin rpy="0 0 0" xyz="0 0 0" /><geometry><sphere radius="0.03964679688215256" /></geometry><drake:proximity_properties><drake:rigid_hydroelastic /><drake:mesh_resolution_hint value="1.5" /><drake:hunt_crossley_dissipation value="1.25" /></drake:proximity_properties></collision></link><joint name="right_wrist_roll_link_to_right_wrist_roll_link_sphere1" type="fixed"><parent link="right_wrist_roll_link" /><child link="right_wrist_roll_link_sphere1" /><origin xyz="0.03182702139019966 0.0005708374083042145 0.0001752771931933239" rpy="0 0 0" /></joint><link name="right_wrist_roll_link_sphere2"><inertial><origin xyz="0 0 0" rpy="0 0 0" /><mass value="0.01" /><inertia ixx="0.001" ixy="0" ixz="0" iyy="0.001" iyz="0" izz="0.001" /></inertial><visual><origin rpy="0 0 0" xyz="0 0 0" /><geometry><sphere radius="0.037202272564172745" /></geometry><material name="color_right_wrist_roll_link_sphere2_0"><color rgba="0.4 0.6 0.8 1.0" /></material></visual><collision><origin rpy="0 0 0" xyz="0 0 0" /><geometry><sphere radius="0.037202272564172745" /></geometry><drake:proximity_properties><drake:rigid_hydroelastic /><drake:mesh_resolution_hint value="1.5" /><drake:hunt_crossley_dissipation value="1.25" /></drake:proximity_properties></collision></link><joint name="right_wrist_roll_link_to_right_wrist_roll_link_sphere2" type="fixed"><parent link="right_wrist_roll_link" /><child link="right_wrist_roll_link_sphere2" /><origin xyz="0.05881008878350258 0.0008547790348529816 0.00018974886916112155" rpy="0 0 0" /></joint><link name="right_wrist_pitch_link_sphere1"><inertial><origin xyz="0 0 0" rpy="0 0 0" /><mass value="0.01" /><inertia ixx="0.001" ixy="0" ixz="0" iyy="0.001" iyz="0" izz="0.001" /></inertial><visual><origin rpy="0 0 0" xyz="0 0 0" /><geometry><sphere radius="0.016422079876065254" /></geometry><material name="color_right_wrist_pitch_link_sphere1_0"><color rgba="0.3 0.7 0.9 1.0" /></material></visual><collision><origin rpy="0 0 0" xyz="0 0 0" /><geometry><sphere radius="0.016422079876065254" /></geometry><drake:proximity_properties><drake:rigid_hydroelastic /><drake:mesh_resolution_hint value="1.5" /><drake:hunt_crossley_dissipation value="1.25" /></drake:proximity_properties></collision></link><joint name="right_wrist_pitch_link_to_right_wrist_pitch_link_sphere1" type="fixed"><parent link="right_wrist_pitch_link" /><child link="right_wrist_pitch_link_sphere1" /><origin xyz="0.008226626552641392 0.017400745302438736 0.016553251072764397" rpy="0 0 0" /></joint><link name="right_wrist_pitch_link_sphere2"><inertial><origin xyz="0 0 0" rpy="0 0 0" /><mass value="0.01" /><inertia ixx="0.001" ixy="0" ixz="0" iyy="0.001" iyz="0" izz="0.001" /></inertial><visual><origin rpy="0 0 0" xyz="0 0 0" /><geometry><sphere radius="0.03586714342236519" /></geometry><material name="color_right_wrist_pitch_link_sphere2_0"><color rgba="0.3 0.7 0.9 1.0" /></material></visual><collision><origin rpy="0 0 0" xyz="0 0 0" /><geometry><sphere radius="0.03586714342236519" /></geometry><drake:proximity_properties><drake:rigid_hydroelastic /><drake:mesh_resolution_hint value="1.5" /><drake:hunt_crossley_dissipation value="1.25" /></drake:proximity_properties></collision></link><joint name="right_wrist_pitch_link_to_right_wrist_pitch_link_sphere2" type="fixed"><parent link="right_wrist_pitch_link" /><child link="right_wrist_pitch_link_sphere2" /><origin xyz="0.019237935543060303 -0.0004402525373734534 0.0001857509632827714" rpy="0 0 0" /></joint><link name="right_wrist_yaw_link_sphere1"><inertial><origin xyz="0 0 0" rpy="0 0 0" /><mass value="0.01" /><inertia ixx="0.001" ixy="0" ixz="0" iyy="0.001" iyz="0" izz="0.001" /></inertial><visual><origin rpy="0 0 0" xyz="0 0 0" /><geometry><sphere radius="0.024296803399920464" /></geometry><material name="color_right_wrist_yaw_link_sphere1_0"><color rgba="0.2 0.8 0.8 1.0" /></material></visual><collision><origin rpy="0 0 0" xyz="0 0 0" /><geometry><sphere radius="0.024296803399920464" /></geometry><drake:proximity_properties><drake:rigid_hydroelastic /><drake:mesh_resolution_hint value="1.5" /><drake:hunt_crossley_dissipation value="1.25" /></drake:proximity_properties></collision></link><joint name="right_wrist_yaw_link_to_right_wrist_yaw_link_sphere1" type="fixed"><parent link="right_wrist_yaw_link" /><child link="right_wrist_yaw_link_sphere1" /><origin xyz="0.00269945221953094 -9.838795085670426e-05 0.02230464667081833" rpy="0 0 0" /></joint><link name="right_wrist_yaw_link_sphere2"><inertial><origin xyz="0 0 0" rpy="0 0 0" /><mass value="0.01" /><inertia ixx="0.001" ixy="0" ixz="0" iyy="0.001" iyz="0" izz="0.001" /></inertial><visual><origin rpy="0 0 0" xyz="0 0 0" /><geometry><sphere radius="0.038393523544073105" /></geometry><material name="color_right_wrist_yaw_link_sphere2_0"><color rgba="0.2 0.8 0.8 1.0" /></material></visual><collision><origin rpy="0 0 0" xyz="0 0 0" /><geometry><sphere radius="0.038393523544073105" /></geometry><drake:proximity_properties><drake:rigid_hydroelastic /><drake:mesh_resolution_hint value="1.5" /><drake:hunt_crossley_dissipation value="1.25" /></drake:proximity_properties></collision></link><joint name="right_wrist_yaw_link_to_right_wrist_yaw_link_sphere2" type="fixed"><parent link="right_wrist_yaw_link" /><child link="right_wrist_yaw_link_sphere2" /><origin xyz="0.026802748441696167 -0.00021777150686830282 -0.0033844613935798407" rpy="0 0 0" /></joint><link name="L_hand_base_link_sphere1"><inertial><origin xyz="0 0 0" rpy="0 0 0" /><mass value="0.01" /><inertia ixx="0.001" ixy="0" ixz="0" iyy="0.001" iyz="0" izz="0.001" /></inertial><visual><origin rpy="0 0 0" xyz="0 0 0" /><geometry><sphere radius="0.033775027841329575" /></geometry><material name="color_L_hand_base_link_sphere1_0"><color rgba="0.2 0.9 0.9 1.0" /></material></visual><collision><origin rpy="0 0 0" xyz="0 0 0" /><geometry><sphere radius="0.033775027841329575" /></geometry><drake:proximity_properties><drake:rigid_hydroelastic /><drake:mesh_resolution_hint value="1.5" /><drake:hunt_crossley_dissipation value="1.25" /></drake:proximity_properties></collision></link><joint name="L_hand_base_link_to_L_hand_base_link_sphere1" type="fixed"><parent link="L_hand_base_link" /><child link="L_hand_base_link_sphere1" /><origin xyz="-0.0004014380683656782 -0.031197713688015938 -0.0007259317790158093" rpy="0 0 0" /></joint><link name="L_hand_base_link_sphere2"><inertial><origin xyz="0 0 0" rpy="0 0 0" /><mass value="0.01" /><inertia ixx="0.001" ixy="0" ixz="0" iyy="0.001" iyz="0" izz="0.001" /></inertial><visual><origin rpy="0 0 0" xyz="0 0 0" /><geometry><sphere radius="0.03365335986018181" /></geometry><material name="color_L_hand_base_link_sphere2_0"><color rgba="0.2 0.9 0.9 1.0" /></material></visual><collision><origin rpy="0 0 0" xyz="0 0 0" /><geometry><sphere radius="0.03365335986018181" /></geometry><drake:proximity_properties><drake:rigid_hydroelastic /><drake:mesh_resolution_hint value="1.5" /><drake:hunt_crossley_dissipation value="1.25" /></drake:proximity_properties></collision></link><joint name="L_hand_base_link_to_L_hand_base_link_sphere2" type="fixed"><parent link="L_hand_base_link" /><child link="L_hand_base_link_sphere2" /><origin xyz="0.0010472703725099564 -0.09967097640037537 -0.0021824550349265337" rpy="0 0 0" /></joint><link name="R_hand_base_link_sphere1"><inertial><origin xyz="0 0 0" rpy="0 0 0" /><mass value="0.01" /><inertia ixx="0.001" ixy="0" ixz="0" iyy="0.001" iyz="0" izz="0.001" /></inertial><visual><origin rpy="0 0 0" xyz="0 0 0" /><geometry><sphere radius="0.0335221029818058" /></geometry><material name="color_R_hand_base_link_sphere1_0"><color rgba="0.9 0.6 0.2 1.0" /></material></visual><collision><origin rpy="0 0 0" xyz="0 0 0" /><geometry><sphere radius="0.0335221029818058" /></geometry><drake:proximity_properties><drake:rigid_hydroelastic /><drake:mesh_resolution_hint value="1.5" /><drake:hunt_crossley_dissipation value="1.25" /></drake:proximity_properties></collision></link><joint name="R_hand_base_link_to_R_hand_base_link_sphere1" type="fixed"><parent link="R_hand_base_link" /><child link="R_hand_base_link_sphere1" /><origin xyz="0.0015398411778733134 -0.10000196844339371 0.0014585518511012197" rpy="0 0 0" /></joint><link name="R_hand_base_link_sphere2"><inertial><origin xyz="0 0 0" rpy="0 0 0" /><mass value="0.01" /><inertia ixx="0.001" ixy="0" ixz="0" iyy="0.001" iyz="0" izz="0.001" /></inertial><visual><origin rpy="0 0 0" xyz="0 0 0" /><geometry><sphere radius="0.03400719165802002" /></geometry><material name="color_R_hand_base_link_sphere2_0"><color rgba="0.9 0.6 0.2 1.0" /></material></visual><collision><origin rpy="0 0 0" xyz="0 0 0" /><geometry><sphere radius="0.03400719165802002" /></geometry><drake:proximity_properties><drake:rigid_hydroelastic /><drake:mesh_resolution_hint value="1.5" /><drake:hunt_crossley_dissipation value="1.25" /></drake:proximity_properties></collision></link><joint name="R_hand_base_link_to_R_hand_base_link_sphere2" type="fixed"><parent link="R_hand_base_link" /><child link="R_hand_base_link_sphere2" /><origin xyz="-0.0008483440615236759 -0.031556762754917145 0.0007022713543847203" rpy="0 0 0" /></joint></robot>
